Workbook
Name A: #REF!
Name A: #REF!
Name A: #REF!
Name A: #REF!
Name AA: #REF!
Name AA: #REF!
Name AA: #REF!
Name AA: #REF!
Name AB: #REF!
Name AB: #REF!
Name AB: #REF!
Name AB: #REF!
Name AC: #REF!
Name AC: #REF!
Name AC: #REF!
Name AD: #REF!
Name AD: #REF!
Name AD: #REF!
Name AE: #REF!
Name AE: #REF!
Name AE: #REF!
Name AE: #REF!
Name AF: #REF!
Name AF: #REF!
Name AF: #REF!
Name AF: #REF!
Name as: #REF!
Name ASD: #REF!
Name asfsdfgfgjgh: #REF!
Name B: #REF!
Name B: #REF!
Name B: #REF!
Name CalH_1: #REF!
Name CalH_10: #REF!
Name CalH_2: #REF!
Name CalH_3: #REF!
Name CalH_4: #REF!
Name CalH_5: #REF!
Name CalH_6: #REF!
Name CalH_7: #REF!
Name CalH_8: #REF!
Name CalH_9: #REF!
Name CL: #REF!
Name CumH_1: #REF!
Name CumH_10: #REF!
Name CumH_11: #REF!
Name CumH_2: #REF!
Name CumH_3: #REF!
Name CumH_4: #REF!
Name CumH_5: #REF!
Name CumH_6: #REF!
Name CumH_7: #REF!
Name CumH_8: #REF!
Name CumH_9: #REF!
Name D: #REF!
Name D: #REF!
Name D: #REF!
Name E: #REF!
Name E: #REF!
Name E: #REF!

Sheet INDEX
F1: 1.15 - PIPING MATERIAL SPECIFICATION INDEX | L1: 11 | Q1: 16 | R1: 17 | S1: 18 | T1: 19 | U1: 20 | V1: 21 | W1: 22 | X1: 23 | Y1: 24 | Z1: 25 | AA1: 26 | AB1: 27 | AC1: 28 | AD1: 29 | AE1: 30 | AF1: 31 | AG1: 32 | AH1: 33
A2: SL No. | B2: SPEC | C2: RATING | D2: ASME MATERIAL GROUP | E2: PIPE MATERIAL | F2: CORROSION ALLOWANCE | G2: SERVICE | H2: MaxPressure @ Min Temp (barg) | I2: MaxPressure @ Max Temp (barg) | J2: Sheet No. | L2: Link | Q2: Branch Chart | R2: Mill Tol | S2: Design Code | T2: MIN TEMP (°C) | U2: 38 | V2: 50 | W2: 100 | X2: 150 | Y2: 200 | Z2: 250 | AA2: 300 | AB2: 350 | AC2: 400 | AD2: 450 | AE2: 500 | AG2: HT | AH2: Valve Material Code
A3: 1 | B3: A1 | C3: 150# | D3: 1.1 | E3: CS | F3: 3 mm | G3: Cooling Water, Diesel, Steam, WI, HC with low CO2 and H2S, Fresh Water, Hydraulic, Nitrogen, Exhaust, Fuel Oil, Tank Air Vent | H3: 19.6 @ -29°C | I3: 13.8 @ 200°C | J3: 24 | L3: =HYPERLINK("#'"&B3&"'!A1",B3) -> A1 | Q3: Ref. APPENDIX-1, Chart 1 | R3: 0.125 | S3: ASME B 31.3 | T3: -29 | U3: 19.6 | V3: 19.2 | W3: 17.7 | X3: 15.8 | Y3: 13.8 | Z3: 12.1 | AF3: =INDIRECT("'"&$L3&"'!$F$3") -> #VALUE! | AG3: =U3*1.5 -> 29.4 | AH3: A1
A4: 2 | B4: B1 | C4: 300# | D4: 1.1 | E4: CS | F4: 3 mm | G4: Cooling Water, Diesel, WI, HC with low CO2 and H2S, Steam, Hydraulic | H4: 51.1 @ -29°C | I4: 43.8 @ 200°C | J4: 25 | L4: =HYPERLINK("#'"&B4&"'!A1",B4) -> B1 | Q4: Ref. APPENDIX-1, Chart 1 | R4: 0.125 | S4: ASME B 31.3 | T4: -29 | U4: 51.1 | V4: 50.1 | W4: 46.6 | X4: 45.1 | Y4: 43.8 | Z4: 41.9 | AF4: =INDIRECT("'"&$L4&"'!$F$3") -> #VALUE! | AG4: =U4*1.5 -> 76.65 | AH4: B1
A5: 3 | B5: D1 | C5: 600# | D5: 1.1 | E5: CS | F5: 3 mm | G5: Cooling Water, Diesel, WI, HC with low CO2 and H2S, Steam, Hydraulic | H5: 102.1 @ -29°C | I5: 87.6 @ 200°C | J5: 26 | L5: =HYPERLINK("#'"&B5&"'!A1",B5) -> D1 | Q5: Ref. APPENDIX-1, Chart 1 | R5: 0.125 | S5: ASME B 31.3 | T5: -29 | U5: 102.1 | V5: 100.2 | W5: 93.2 | X5: 90.2 | Y5: 87.6 | Z5: 83.9 | AF5: =INDIRECT("'"&$L5&"'!$F$3") -> #VALUE! | AG5: =U5*1.5 -> 153.15 | AH5: D1
A6: 4 | B6: E1 | C6: 900# | D6: 1.1 | E6: CS | F6: 3 mm | G6: Diesel, WI, HC with low CO2 and H2S, Steam, Hydraulic | H6: 153.2 @ -29°C | I6: 131.4 @ 200°C | J6: 27 | L6: =HYPERLINK("#'"&B6&"'!A1",B6) -> E1 | Q6: Ref. APPENDIX-1, Chart 1 | R6: 0.125 | S6: ASME B 31.3 | T6: -29 | U6: 153.2 | V6: 150.4 | W6: 139.8 | X6: 135.2 | Y6: 131.4 | Z6: 125.8 | AF6: =INDIRECT("'"&$L6&"'!$F$3") -> #VALUE! | AG6: =U6*1.5 -> 229.8 | AH6: E1
A7: 5 | B7: F1 | C7: 1500# | D7: 1.1 | E7: CS | F7: 3 mm | G7: Diesel, WI, HC with low CO2 and H2S, Steam, Hydraulic | H7: 255.3 @ -29°C | I7: 219 @ 200°C | J7: 28 | L7: =HYPERLINK("#'"&B7&"'!A1",B7) -> F1 | Q7: Ref. APPENDIX-1, Chart 1 | R7: 0.125 | S7: ASME B 31.3 | T7: -29 | U7: 255.3 | V7: 250.6 | W7: 233 | X7: 225.4 | Y7: 219 | Z7: 209.7 | AF7: =INDIRECT("'"&$L7&"'!$F$3") -> #VALUE! | AG7: =U7*1.5 -> 382.95 | AH7: F1
A8: 6 | B8: G1 | C8: 2500# | D8: 1.1 | E8: CS | F8: 3 mm | G8: HC with low CO2 and H2S, Steam, Hydraulic | H8: 399.8 @ -29°C | I8: 342.9 @ 200°C | J8: 29 | L8: =HYPERLINK("#'"&B8&"'!A1",B8) -> G1 | Q8: Ref. APPENDIX-1, Chart 1 | R8: 0.125 | S8: ASME B 31.3 | T8: -29 | U8: 399.8 | V8: 392.4 | W8: 364.8 | X8: 352.9 | Y8: 342.9 | AF8: =INDIRECT("'"&$L8&"'!$F$3") -> #VALUE! | AG8: =U8*1.5 -> 599.7 | AH8: G1
A9: 7 | B9: A1N | C9: 150# | D9: 1.1 | E9: CS NACE | F9: 3 mm | G9: Glycol, FG, HC service | H9: 19.6 @ -29°C | I9: 13.8 @ 250°C | J9: 30 | L9: =HYPERLINK("#'"&B9&"'!A1",B9) -> A1N | Q9: Ref. APPENDIX-1, Chart 1 | R9: 0.125 | S9: ASME B 31.3, NACE-MR-01-75/ISO-15156-1/2/3 | T9: -29 | U9: 19.6 | V9: 19.2 | W9: 17.7 | X9: 15.8 | Y9: 13.8 | Z9: 12.1 | AF9: =INDIRECT("'"&$L9&"'!$F$3") -> #VALUE! | AG9: =U9*1.5 -> 29.4 | AH9: A1N
A10: 8 | B10: B1N | C10: 300# | D10: 1.1 | E10: CS NACE | F10: 3 mm | G10: Glycol, FG, HC service | H10: 51.1 @ -29°C | I10: 43.8 @ 250°C | J10: 31 | L10: =HYPERLINK("#'"&B10&"'!A1",B10) -> B1N | Q10: Ref. APPENDIX-1, Chart 1 | R10: 0.125 | S10: ASME B 31.3, NACE-MR-01-75/ISO-15156-1/2/3 | T10: -29 | U10: 51.1 | V10: 50.1 | W10: 46.6 | X10: 45.1 | Y10: 43.8 | Z10: 41.9 | AF10: =INDIRECT("'"&$L10&"'!$F$3") -> #VALUE! | AG10: =U10*1.5 -> 76.65 | AH10: B1N
A11: 9 | B11: D1N | C11: 600# | D11: 1.1 | E11: CS NACE | F11: 3 mm | G11: Glycol, FG, HC service | H11: 102.1 @ -29°C | I11: 87.6 @ 250°C | J11: 32 | L11: =HYPERLINK("#'"&B11&"'!A1",B11) -> D1N | Q11: Ref. APPENDIX-1, Chart 1 | R11: 0.125 | S11: ASME B 31.3, NACE-MR-01-75/ISO-15156-1/2/3 | T11: -29 | U11: 102.1 | V11: 100.2 | W11: 93.2 | X11: 90.2 | Y11: 87.6 | Z11: 83.9 | AF11: =INDIRECT("'"&$L11&"'!$F$3") -> #VALUE! | AG11: =U11*1.5 -> 153.15 | AH11: D1N
A12: 10 | B12: E1N | C12: 900# | D12: 1.1 | E12: CS NACE | F12: 3 mm | G12: Glycol, FG, HC service | H12: 153.2 @ -29°C | I12: 131.4 @ 250°C | J12: 33 | L12: =HYPERLINK("#'"&B12&"'!A1",B12) -> E1N | Q12: Ref. APPENDIX-1, Chart 1 | R12: 0.125 | S12: ASME B 31.3, NACE-MR-01-75/ISO-15156-1/2/3 | T12: -29 | U12: 153.2 | V12: 150.4 | W12: 139.8 | X12: 135.2 | Y12: 131.4 | Z12: 125.8 | AF12: =INDIRECT("'"&$L12&"'!$F$3") -> #VALUE! | AG12: =U12*1.5 -> 229.8 | AH12: E1N
A13: 11 | B13: F1N | C13: 1500# | D13: 1.1 | E13: CS NACE | F13: 3 mm | G13: Glycol, FG, HC service | H13: 255.3 @ -29°C | I13: 219 @ 200°C | J13: 34 | L13: =HYPERLINK("#'"&B13&"'!A1",B13) -> F1N | Q13: Ref. APPENDIX-1, Chart 1 | R13: 0.125 | S13: ASME B 31.3, NACE-MR-01-75/ISO-15156-1/2/3 | T13: -29 | U13: 255.3 | V13: 250.6 | W13: 233 | X13: 225.4 | Y13: 219 | Z13: 209.7 | AF13: =INDIRECT("'"&$L13&"'!$F$3") -> #VALUE! | AG13: =U13*1.5 -> 382.95 | AH13: F1N
A14: 12 | B14: G1N | C14: 2500# | D14: 1.1 | E14: CS NACE | F14: 3 mm | G14: Glycol, FG, HC service | H14: 399.8 @ -29°C | I14: 342.9 @ 200°C | J14: 35 | L14: =HYPERLINK("#'"&B14&"'!A1",B14) -> G1N | Q14: Ref. APPENDIX-1, Chart 1 | R14: 0.125 | S14: ASME B 31.3, NACE-MR-01-75/ISO-15156-1/2/3 | T14: -29 | U14: 399.8 | V14: 392.4 | W14: 364.8 | X14: 352.9 | Y14: 342.9 | AF14: =INDIRECT("'"&$L14&"'!$F$3") -> #VALUE! | AG14: =U14*1.5 -> 599.7 | AH14: G1N
A15: 13 | B15: A2 | C15: 150# | D15: 1.1 | E15: CS | F15: 6 mm | G15: Crude Oil | H15: 19.6 @ -29°C | I15: 13.8 @ 200°C | J15: 36 | L15: =HYPERLINK("#'"&B15&"'!A1",B15) -> A2 | Q15: Ref. APPENDIX-1, Chart 1 | R15: 0.125 | S15: ASME B 31.3 | T15: -29 | U15: 19.6 | V15: 19.2 | W15: 17.7 | X15: 15.8 | Y15: 13.8 | Z15: 12.1 | AF15: =INDIRECT("'"&$L15&"'!$F$3") -> #VALUE! | AG15: =U15*1.5 -> 29.4 | AH15: A2
A16: 14 | B16: A2N | C16: 150# | D16: 1.1 | E16: CS NACE | F16: 6 mm | G16: Corrosive HC service | H16: 19.6 @ -29°C | I16: 13.8 @ 200°C | J16: 37 | L16: =HYPERLINK("#'"&B16&"'!A1",B16) -> A2N | Q16: Ref. APPENDIX-1, Chart 1 | R16: 0.125 | S16: ASME B 31.3, NACE-MR-01-75/ISO-15156-1/2/3 | T16: -29 | U16: 19.6 | V16: 19.2 | W16: 17.7 | X16: 15.8 | Y16: 13.8 | Z16: 12.1 | AF16: =INDIRECT("'"&$L16&"'!$F$3") -> #VALUE! | AG16: =U16*1.5 -> 29.4 | AH16: =INDIRECT("'"&$L16&"'!$F$3") -> #VALUE!
A17: 15 | B17: B2N | C17: 300# | D17: 1.1 | E17: CS NACE | F17: 6 mm | G17: Corrosive HC service | H17: 51.1 @ -29°C | I17: 43.8 @ 200°C | J17: 38 | L17: =HYPERLINK("#'"&B17&"'!A1",B17) -> B2N | Q17: Ref. APPENDIX-1, Chart 1 | R17: 0.125 | S17: ASME B 31.3, NACE-MR-01-75/ISO-15156-1/2/3 | T17: -29 | U17: 51.1 | V17: 50.1 | W17: 46.6 | X17: 45.1 | Y17: 43.8 | Z17: 41.9 | AF17: =INDIRECT("'"&$L17&"'!$F$3") -> #VALUE! | AG17: =U17*1.5 -> 76.65 | AH17: =INDIRECT("'"&$L17&"'!$F$3") -> #VALUE!
A18: 16 | B18: D2N | C18: 600# | D18: 1.1 | E18: CS NACE | F18: 6 mm | G18: Corrosive HC service | H18: 102.1 @ -29°C | I18: 87.6 @ 200°C | J18: 39 | L18: =HYPERLINK("#'"&B18&"'!A1",B18) -> D2N | Q18: Ref. APPENDIX-1, Chart 1 | R18: 0.125 | S18: ASME B 31.3, NACE-MR-01-75/ISO-15156-1/2/3 | T18: -29 | U18: 102.1 | V18: 100.2 | W18: 93.2 | X18: 90.2 | Y18: 87.6 | Z18: 83.9 | AF18: =INDIRECT("'"&$L18&"'!$F$3") -> #VALUE! | AG18: =U18*1.5 -> 153.15 | AH18: =INDIRECT("'"&$L18&"'!$F$3") -> #VALUE!
A19: 17 | B19: E2N | C19: 900# | D19: 1.1 | E19: CS NACE | F19: 6 mm | G19: Corrosive HC service | H19: 153.2 @ -29°C | I19: 131.4 @ 200°C | J19: 40 | L19: =HYPERLINK("#'"&B19&"'!A1",B19) -> E2N | Q19: Ref. APPENDIX-1, Chart 1 | R19: 0.125 | S19: ASME B 31.3, NACE-MR-01-75/ISO-15156-1/2/3 | T19: -29 | U19: 153.2 | V19: 150.4 | W19: 139.8 | X19: 135.2 | Y19: 131.4 | Z19: 125.8 | AF19: =INDIRECT("'"&$L19&"'!$F$3") -> #VALUE! | AG19: =U19*1.5 -> 229.8 | AH19: =INDIRECT("'"&$L19&"'!$F$3") -> #VALUE!
A20: 18 | B20: F2N | C20: 1500# | D20: 1.1 | E20: CS NACE | F20: 6 mm | G20: Corrosive HC service | H20: 255.3 @ -29°C | I20: 219 @ 200°C | J20: 41 | L20: =HYPERLINK("#'"&B20&"'!A1",B20) -> F2N | Q20: Ref. APPENDIX-1, Chart 1 | R20: 0.125 | S20: ASME B 31.3, NACE-MR-01-75/ISO-15156-1/2/3 | T20: -29 | U20: 255.3 | V20: 250.6 | W20: 233 | X20: 225.4 | Y20: 219 | Z20: 209.7 | AF20: =INDIRECT("'"&$L20&"'!$F$3") -> #VALUE! | AG20: =U20*1.5 -> 382.95 | AH20: =INDIRECT("'"&$L20&"'!$F$3") -> #VALUE!
A21: 19 | B21: G2N | C21: 2500# | D21: 1.1 | E21: CS NACE | F21: 6 mm | G21: Corrosive HC service | H21: 399.8 @ -29°C | I21: 342.9 @ 200°C | J21: 42 | L21: =HYPERLINK("#'"&B21&"'!A1",B21) -> G2N | Q21: Ref. APPENDIX-1, Chart 1 | R21: 0.125 | S21: ASME B 31.3, NACE-MR-01-75/ISO-15156-1/2/3 | T21: -29 | U21: 399.8 | V21: 392.4 | W21: 364.8 | X21: 352.9 | Y21: 342.9 | AF21: =INDIRECT("'"&$L21&"'!$F$3") -> #VALUE! | AG21: =U21*1.5 -> 599.7 | AH21: =INDIRECT("'"&$L21&"'!$F$3") -> #VALUE!
A22: 20 | B22: A1LN | C22: 150# | D22: 1.1 | E22: LTCS NACE | F22: 3 mm | G22: Flare, Corrosive HC service (Low Temp) | H22: 19.6 @ -45°C | I22: 13.8 @ 200°C | J22: 43 | L22: =HYPERLINK("#'"&B22&"'!A1",B22) -> A1LN | Q22: Ref. APPENDIX-1, Chart 1 | R22: 0.125 | S22: ASME B 31.3, NACE-MR-01-75/ISO-15156-1/2/3 | T22: -45 | U22: 19.6 | V22: 19.2 | W22: 17.7 | X22: 15.8 | Y22: 13.8 | Z22: 12.1 | AF22: =INDIRECT("'"&$L22&"'!$F$3") -> #VALUE! | AG22: =U22*1.5 -> 29.4 | AH22: =INDIRECT("'"&$L22&"'!$F$3") -> #VALUE!
A23: 21 | B23: B1LN | C23: 300# | D23: 1.1 | E23: LTCS NACE | F23: 3 mm | G23: Flare, Corrosive HC service (Low Temp) | H23: 51.1 @ -45°C | I23: 43.8 @ 200°C | J23: 44 | L23: =HYPERLINK("#'"&B23&"'!A1",B23) -> B1LN | Q23: Ref. APPENDIX-1, Chart 1 | R23: 0.125 | S23: ASME B 31.3, NACE-MR-01-75/ISO-15156-1/2/3 | T23: -45 | U23: 51.1 | V23: 50.1 | W23: 46.6 | X23: 45.1 | Y23: 43.8 | Z23: 41.9 | AF23: =INDIRECT("'"&$L23&"'!$F$3") -> #VALUE! | AG23: =U23*1.5 -> 76.65 | AH23: =INDIRECT("'"&$L23&"'!$F$3") -> #VALUE!
A24: 22 | B24: D1LN | C24: 600# | D24: 1.1 | E24: LTCS NACE | F24: 3 mm | G24: Corrosive HC service (Low Temp) | H24: 102.1 @ -45°C | I24: 87.6 @ 200°C | J24: 45 | L24: =HYPERLINK("#'"&B24&"'!A1",B24) -> D1LN | Q24: Ref. APPENDIX-1, Chart 1 | R24: 0.125 | S24: ASME B 31.3, NACE-MR-01-75/ISO-15156-1/2/3 | T24: -45 | U24: 102.1 | V24: 100.2 | W24: 93.2 | X24: 90.2 | Y24: 87.6 | Z24: 83.9 | AF24: =INDIRECT("'"&$L24&"'!$F$3") -> #VALUE! | AG24: =U24*1.5 -> 153.15 | AH24: =INDIRECT("'"&$L24&"'!$F$3") -> #VALUE!
A25: 23 | B25: E1LN | C25: 900# | D25: 1.1 | E25: LTCS NACE | F25: 3 mm | G25: Corrosive HC service (Low Temp) | H25: 153.2 @ -45°C | I25: 131.4 @ 200°C | J25: 46 | L25: =HYPERLINK("#'"&B25&"'!A1",B25) -> E1LN | Q25: Ref. APPENDIX-1, Chart 1 | R25: 0.125 | S25: ASME B 31.3, NACE-MR-01-75/ISO-15156-1/2/3 | T25: -45 | U25: 153.2 | V25: 150.4 | W25: 139.8 | X25: 135.2 | Y25: 131.4 | Z25: 125.8 | AF25: =INDIRECT("'"&$L25&"'!$F$3") -> #VALUE! | AG25: =U25*1.5 -> 229.8 | AH25: =INDIRECT("'"&$L25&"'!$F$3") -> #VALUE!
A26: 24 | B26: F1LN | C26: 1500# | D26: 1.1 | E26: LTCS NACE | F26: 3 mm | G26: Corrosive HC service (Low Temp) | H26: 255.3 @ -45°C | I26: 219 @ 200°C | J26: 47 | L26: =HYPERLINK("#'"&B26&"'!A1",B26) -> F1LN | Q26: Ref. APPENDIX-1, Chart 1 | R26: 0.125 | S26: ASME B 31.3, NACE-MR-01-75/ISO-15156-1/2/3 | T26: -45 | U26: 255.3 | V26: 250.6 | W26: 233 | X26: 225.4 | Y26: 219 | Z26: 209.7 | AF26: =INDIRECT("'"&$L26&"'!$F$3") -> #VALUE! | AG26: =U26*1.5 -> 382.95 | AH26: =INDIRECT("'"&$L26&"'!$F$3") -> #VALUE!
A27: 25 | B27: G1LN | C27: 2500# | D27: 1.1 | E27: LTCS NACE | F27: 3 mm | G27: Gas Lift, Corrosive HC service (Low Temp) | H27: 399.8 @ -29°C | I27: 342.9 @ 200°C | J27: 48 | L27: =HYPERLINK("#'"&B27&"'!A1",B27) -> G1LN | Q27: Ref. APPENDIX-1, Chart 1 | R27: 0.125 | S27: ASME B 31.3, NACE-MR-01-75/ISO-15156-1/2/3 | T27: -45 | U27: 399.8 | V27: 392.4 | W27: 364.8 | X27: 352.9 | Y27: 342.9 | AF27: =INDIRECT("'"&$L27&"'!$F$3") -> #VALUE! | AG27: =U27*1.5 -> 599.7 | AH27: =INDIRECT("'"&$L27&"'!$F$3") -> #VALUE!
A28: 26 | B28: A2LN | C28: 150# | D28: 1.1 | E28: LTCS NACE | F28: 6 mm | G28: Corrosive HC service (Low Temp) | H28: 19.6 @ -45°C | I28: 13.8 @ 200°C | J28: 49 | L28: =HYPERLINK("#'"&B28&"'!A1",B28) -> A2LN | Q28: Ref. APPENDIX-1, Chart 1 | R28: 0.125 | S28: ASME B 31.3, NACE-MR-01-75/ISO-15156-1/2/3 | T28: -45 | U28: 19.6 | V28: 19.2 | W28: 17.7 | X28: 15.8 | Y28: 13.8 | Z28: 12.1 | AF28: =INDIRECT("'"&$L28&"'!$F$3") -> #VALUE! | AG28: =U28*1.5 -> 29.4 | AH28: =INDIRECT("'"&$L28&"'!$F$3") -> #VALUE!
A29: 27 | B29: B2LN | C29: 300# | D29: 1.1 | E29: LTCS NACE | F29: 6 mm | G29: Corrosive HC service (Low Temp) | H29: 51.1 @ -45°C | I29: 43.8 @ 200°C | J29: 50 | L29: =HYPERLINK("#'"&B29&"'!A1",B29) -> B2LN | Q29: Ref. APPENDIX-1, Chart 1 | R29: 0.125 | S29: ASME B 31.3, NACE-MR-01-75/ISO-15156-1/2/3 | T29: -45 | U29: 51.1 | V29: 50.1 | W29: 46.6 | X29: 45.1 | Y29: 43.8 | Z29: 41.9 | AF29: =INDIRECT("'"&$L29&"'!$F$3") -> #VALUE! | AG29: =U29*1.5 -> 76.65 | AH29: =INDIRECT("'"&$L29&"'!$F$3") -> #VALUE!
A30: 28 | B30: D2LN | C30: 600# | D30: 1.1 | E30: LTCS NACE | F30: 6 mm | G30: Corrosive HC service (Low Temp) | H30: 102.1 @ -45°C | I30: 87.6 @ 200°C | J30: 51 | L30: =HYPERLINK("#'"&B30&"'!A1",B30) -> D2LN | Q30: Ref. APPENDIX-1, Chart 1 | R30: 0.125 | S30: ASME B 31.3, NACE-MR-01-75/ISO-15156-1/2/3 | T30: -45 | U30: 102.1 | V30: 100.2 | W30: 93.2 | X30: 90.2 | Y30: 87.6 | Z30: 83.9 | AF30: =INDIRECT("'"&$L30&"'!$F$3") -> #VALUE! | AG30: =U30*1.5 -> 153.15 | AH30: =INDIRECT("'"&$L30&"'!$F$3") -> #VALUE!
A31: 29 | B31: E2LN | C31: 900# | D31: 1.1 | E31: LTCS NACE | F31: 6 mm | G31: Corrosive HC service (Low Temp) | H31: 153.2 @ -45°C | I31: 131.4 @ 200°C | J31: 52 | L31: =HYPERLINK("#'"&B31&"'!A1",B31) -> E2LN | Q31: Ref. APPENDIX-1, Chart 1 | R31: 0.125 | S31: ASME B 31.3, NACE-MR-01-75/ISO-15156-1/2/3 | T31: -45 | U31: 153.2 | V31: 150.4 | W31: 139.8 | X31: 135.2 | Y31: 131.4 | Z31: 125.8 | AF31: =INDIRECT("'"&$L31&"'!$F$3") -> #VALUE! | AG31: =U31*1.5 -> 229.8 | AH31: =INDIRECT("'"&$L31&"'!$F$3") -> #VALUE!
A32: 30 | B32: F2LN | C32: 1500# | D32: 1.1 | E32: LTCS NACE | F32: 6 mm | G32: Corrosive HC service (Low Temp) | H32: 255.3 @ -45°C | I32: 219 @ 200°C | J32: 53 | L32: =HYPERLINK("#'"&B32&"'!A1",B32) -> F2LN | Q32: Ref. APPENDIX-1, Chart 1 | R32: 0.125 | S32: ASME B 31.3, NACE-MR-01-75/ISO-15156-1/2/3 | T32: -45 | U32: 255.3 | V32: 250.6 | W32: 233 | X32: 225.4 | Y32: 219 | Z32: 209.7 | AF32: =INDIRECT("'"&$L32&"'!$F$3") -> #VALUE! | AG32: =U32*1.5 -> 382.95 | AH32: =INDIRECT("'"&$L32&"'!$F$3") -> #VALUE!
A33: 31 | B33: G2LN | C33: 2500# | D33: 1.1 | E33: LTCS NACE | F33: 6 mm | G33: Corrosive HC service (Low Temp) | H33: 399.8 @ -29°C | I33: 342.9 @ 200°C | J33: 54 | L33: =HYPERLINK("#'"&B33&"'!A1",B33) -> G2LN | Q33: Ref. APPENDIX-1, Chart 1 | R33: 0.125 | S33: ASME B 31.3, NACE-MR-01-75/ISO-15156-1/2/3 | T33: -45 | U33: 399.8 | V33: 392.4 | W33: 364.8 | X33: 352.9 | Y33: 342.9 | AF33: =INDIRECT("'"&$L33&"'!$F$3") -> #VALUE! | AG33: =U33*1.5 -> 599.7 | AH33: =INDIRECT("'"&$L33&"'!$F$3") -> #VALUE!
A34: 32 | B34: A3 | C34: 150# | D34: 1.1 | E34: CS GALV (Valve: SS) | F34: 3 mm | G34: Utility Water | H34: 19 @ -29°C | I34: 16.2 @ 100°C | J34: 55 | L34: =HYPERLINK("#'"&B34&"'!A1",B34) -> A3 | Q34: Ref. APPENDIX-1, Chart 2 | R34: 0.125 | S34: ASME B 31.3 | T34: -29 | U34: 15.9 | V34: 15.3 | W34: 13.3 | X34: 12 | Y34: 11.2 | Z34: 10.5 | AF34: =INDIRECT("'"&$L34&"'!$F$3") -> #VALUE! | AG34: =U34*1.5 -> 23.85 | AH34: A10
A35: 33 | B35: A4 | C35: 150# | D35: 1.1 | E35: CS GALV (Valve: SS) | F35: 1.5 mm | G35: Bilge, drain, sewage, produced water, C02 Gas | H35: 19 @ -29°C | I35: 16.2 @ 100°C | J35: 56 | L35: =HYPERLINK("#'"&B35&"'!A1",B35) -> A4 | Q35: Ref. APPENDIX-1, Chart 2 | R35: 0.125 | S35: ASME B 31.3 | T35: -29 | U35: 15.9 | V35: 15.3 | W35: 13.3 | X35: 12 | Y35: 11.2 | Z35: 10.5 | AF35: =INDIRECT("'"&$L35&"'!$F$3") -> #VALUE! | AG35: =U35*1.5 -> 23.85 | AH35: A10
A36: 34 | B36: B4 | C36: 300# | D36: 1.1 | E36: CS GALV (Valve: SS) | F36: 1.5 mm | G36: Bilge, drain, sewage, produced water, C02 Gas | H36: 51.1 @ -29°C | I36: 43.8 @ 250°C | J36: 57 | L36: =HYPERLINK("#'"&B36&"'!A1",B36) -> B4 | Q36: Ref. APPENDIX-1, Chart 2 | R36: 0.125 | S36: ASME B 31.3 | T36: -29 | U36: 51.1 | V36: 50.1 | W36: 46.6 | X36: 45.1 | Y36: 43.8 | Z36: 41.9 | AF36: =INDIRECT("'"&$L36&"'!$F$3") -> #VALUE! | AG36: =U36*1.5 -> 76.65 | AH36: B10
A37: 35 | B37: D4 | C37: 600# | D37: 1.1 | E37: CS GALV (Valve: SS) | F37: 1.5 mm | G37: Bilge, drain, sewage, produced water, C02 Gas | H37: 102.1 @ -29°C | I37: 87.6 @ 250°C | J37: 58 | L37: =HYPERLINK("#'"&B37&"'!A1",B37) -> D4 | Q37: Ref. APPENDIX-1, Chart 2 | R37: 0.125 | S37: ASME B 31.3 | T37: -29 | U37: 102.1 | V37: 100.2 | W37: 93.2 | X37: 90.2 | Y37: 87.6 | Z37: 83.9 | AF37: =INDIRECT("'"&$L37&"'!$F$3") -> #VALUE! | AG37: =U37*1.5 -> 153.15 | AH37: D10
A38: 36 | B38: A5 | C38: 150# | D38: 1.1 | E38: CS GALV | F38: 6 mm | G38: Chemical (penetration), Firewater (penetration), Seawater (penetration), Ballast, Inert Gas, COW/Tank Cleaning, Slop, Stripping, Seawater | H38: 19 @ -29°C | I38: 16.2 @ 100°C | J38: 59 | L38: =HYPERLINK("#'"&B38&"'!A1",B38) -> A5 | Q38: Ref. APPENDIX-1, Chart 2 | R38: 0.125 | S38: ASME B 31.3 | T38: -29 | U38: 15.9 | V38: 15.3 | W38: 13.3 | X38: 12 | Y38: 11.2 | Z38: 10.5 | AF38: =INDIRECT("'"&$L38&"'!$F$3") -> #VALUE! | AG38: =U38*1.5 -> 23.85 | AH38: A10
A39: 37 | B39: A6 | C39: 150# | D39: 1.1 | E39: CS - Epoxy Lined | F39: 6 mm | G39: Ballast, Inert Gas, COW/Tank Cleaning, Slop, Seawater, Firewater | H39: 19 @ -29°C | I39: 16.2 @ 100°C | J39: 60 | L39: =HYPERLINK("#'"&B39&"'!A1",B39) -> A6 | Q39: Ref. APPENDIX-1, Chart 2 | R39: 0.125 | S39: ASME B 31.3 | T39: -29 | U39: 15.9 | V39: 15.3 | W39: 13.3 | X39: 12 | Y39: 11.2 | Z39: 10.5 | AF39: =INDIRECT("'"&$L39&"'!$F$3") -> #VALUE! | AG39: =U39*1.5 -> 23.85 | AH39: A10
A40: 38 | B40: A10 | C40: 150# | D40: 2.3 | E40: SS316L | F40: NIL | G40: Air, Nitrogen, Lube oil, Chemical, Foam, hydraulic, Instrument Air, Diesel Fuel | H40: 15.9 @ -100°C | I40: 11.2 @ 200°C | J40: 61 | L40: =HYPERLINK("#'"&B40&"'!A1",B40) -> A10 | Q40: Ref. APPENDIX-1, Chart 1 | R40: 0.125 | S40: ASME B 31.3 | T40: -100 | U40: 15.9 | V40: 15.3 | W40: 13.3 | X40: 12 | Y40: 11.2 | Z40: 10.5 | AF40: =INDIRECT("'"&$L40&"'!$F$3") -> #VALUE! | AG40: =U40*1.5 -> 23.85 | AH40: =INDIRECT("'"&$L40&"'!$F$3") -> #VALUE!
...

Sheet A1
A1: #VALUE! | F1: PIPING MATERIAL SPECIFICATION | U1: Rev: C0
F2: Piping Class | J2: Material | N2: C.A | R2: Mill Tol | U2: Sheet No.
F3: =MID(CELL("filename",A4),FIND("]",CELL("filename",A4))+1,255) -> #VALUE! | H3: =VLOOKUP(F3,INDEX!B:J,2,0) -> #VALUE! | J3: =VLOOKUP(F3,INDEX!B:J,4,0) -> #VALUE! | N3: =VLOOKUP(F3,INDEX!B:J,5,0) -> #VALUE! | R3: =VLOOKUP(F3,INDEX!B:AF,17,0) -> #VALUE! | U3: =VLOOKUP(F3,INDEX!B:J,9,0) -> #VALUE!
F4: Design Code: | I4: =VLOOKUP(F3,INDEX!B:AF,18,0) -> #VALUE!
F5: Service: | H5: =VLOOKUP(F3,INDEX!B:J,6,0) -> #VALUE!
F6: Branch Chart: | I6: =VLOOKUP(F3,INDEX!B:AF,16,0) -> #VALUE!
A7: Pressure-Temperature Rating
A8: Press., barg | B8: =VLOOKUP(F3,INDEX!B:AF,20,0) -> #VALUE! | D8: =VLOOKUP(F3,INDEX!B:AF,21,0) -> #VALUE! | F8: =VLOOKUP(F3,INDEX!B:AF,22,0) -> #VALUE! | H8: =VLOOKUP(F3,INDEX!B:AF,23,0) -> #VALUE! | J8: =VLOOKUP(F3,INDEX!B:AF,24,0) -> #VALUE! | P8: Hydrotest Pr. (barg)
A9: Temp., °C | B9: =VLOOKUP(F3,INDEX!B:Z,19,0)&" to 38" -> #VALUE! | D9: 50 | F9: 100 | H9: 150 | J9: 200 | P9: =B8*1.5 -> #VALUE!
A10: Pipe Data
A11: Code | B11: ASME B 36.10M
A12: Size(in) | B12: 0.5 | C12: 0.75 | D12: 1 | E12: 1.5 | F12: 2 | G12: 3 | H12: 4 | I12: 6 | J12: 8 | K12: 10 | L12: 12 | M12: 14 | N12: 16 | O12: 18 | P12: 20 | Q12: 22 | R12: 24 | S12: 26 | T12: 28 | U12: 30 | V12: 32 | W12: 36
A13: O.D.mm | B13: 21.3 | C13: 26.7 | D13: 33.4 | E13: 48.3 | F13: 60.3 | G13: 88.9 | H13: 114.3 | I13: 168.3 | J13: 219.1 | K13: 273.1 | L13: 323.9 | M13: 355.6 | N13: 406.4 | O13: 457 | P13: 508 | Q13: 559 | R13: 610 | S13: 660 | T13: 711 | U13: 762 | V13: 812.8 | W13: 914.4
A14: Sch. | B14: 160 | C14: 160 | D14: 160 | E14: 160 | F14: 80 | G14: 80 | H14: 80 | I14: 80 | J14: STD | K14: STD | L14: STD | M14: STD | N14: STD | O14: STD | P14: STD | Q14: STD | R14: STD | S14: STD | T14: STD | U14: XS | V14: XS | W14: XS
A15: WT. mm | B15: 7.47 | C15: 5.56 | D15: 6.35 | E15: 7.14 | F15: 5.54 | G15: 7.62 | H15: 8.56 | I15: 10.97 | J15: 8.18 | K15: 9.27 | L15: 9.53 | M15: 9.53 | N15: 9.53 | O15: 9.53 | P15: 9.53 | Q15: 9.53 | R15: 9.53 | S15: 9.53 | T15: 9.53 | U15: 12.7 | V15: 12.7 | W15: 12.7
A16: TYPE | B16: Seamless | P16: LSAW, 100% RT
A17: MOC | B17: ASTM A 106 Gr. B | P17: API 5L Gr. B
A18: Ends | B18: BE
A19: Fittings Data
A20: TYPE | B20: Butt Weld (SCH to match pipe), Seamless | P20: Butt Weld (SCH to match pipe), Welded
A21: MOC | B21: ASTM A 234 Gr. WPB
A22: Elbow | B22: ASME B 16.9
A23: Tee | B23: ASME B 16.9
A24: Red. | B24: ASME B 16.9
A25: Cap | B25: ASME B 16.9
A26: Plug | B26: Hex Head, ASME B 16.11
A27: Weldolet | B27: MSS SP 97, ASTM A 105N
A28: Flange
A29: MOC | B29: ASTM A 105N
A30: FACE | B30: 150# RF, Serrated Finish
A31: TYPE | B31: Weld Neck, ASME B 16.5/ 16.47A, Butt Welding ends as per ASME B 16.25
A32: Spectacle Blind/Spacer Blinds
A33: MOC | B33: ASTM A 105N
A34: Spectacle | B34: ASME B 16.48 | N34: Spacer and blind as per ASME B 16.48 (Note 5)
A35: Bolts/ Nuts/ Gaskets
A36: Stud Bolts | B36: ASTM A 193 Gr. B7M, XYLAR 2 + XYLAN 1070 coated with minimum combined thickness of 50μm
A37: Hex Nuts | B37: ASTM A 194 Gr. 2HM, XYLAR 2 + XYLAN 1070 coated with minimum combined thickness of 50μm
A38: Gasket | B38: ASME B 16.20, 4.5mm, SS316/SS316L Spiral Wound with Flexible Graphite (F.G.) filler
A39: Valves
A40: Rating | B40: =VLOOKUP(F3,INDEX!B:J,2,0)&", RF" -> #VALUE!
...

Sheet B1
A1: #VALUE! | F1: PIPING MATERIAL SPECIFICATION | Q1: Rev: C0
F2: Piping Class | J2: Material | M2: C.A | O2: Mill Tol | Q2: Sheet No.
F3: =MID(CELL("filename",A4),FIND("]",CELL("filename",A4))+1,255) -> #VALUE! | H3: =VLOOKUP(F3,INDEX!B:J,2,0) -> #VALUE! | J3: =VLOOKUP(F3,INDEX!B:J,4,0) -> #VALUE! | M3: =VLOOKUP(F3,INDEX!B:J,5,0) -> #VALUE! | O3: =VLOOKUP(F3,INDEX!B:AF,17,0) -> #VALUE! | Q3: =VLOOKUP(F3,INDEX!B:J,9,0) -> #VALUE!
F4: Design Code: | I4: =VLOOKUP(F3,INDEX!B:AF,18,0) -> #VALUE!
F5: Service: | H5: =VLOOKUP(F3,INDEX!B:J,6,0) -> #VALUE!
F6: Branch Chart: | I6: =VLOOKUP(F3,INDEX!B:AF,16,0) -> #VALUE!
A7: Pressure-Temperature Rating
A8: Press., barg | B8: =VLOOKUP(F3,INDEX!B:AF,20,0) -> #VALUE! | D8: =VLOOKUP(F3,INDEX!B:AF,21,0) -> #VALUE! | F8: =VLOOKUP(F3,INDEX!B:AF,22,0) -> #VALUE! | H8: =VLOOKUP(F3,INDEX!B:AF,23,0) -> #VALUE! | J8: =VLOOKUP(F3,INDEX!B:AF,24,0) -> #VALUE! | P8: Hydrotest Pr. (barg)
A9: Temp., °C | B9: =VLOOKUP(F3,INDEX!B:Z,19,0)&" to 38" -> #VALUE! | D9: 50 | F9: 100 | H9: 150 | J9: 200 | P9: =B8*1.5 -> #VALUE!
A10: Pipe Data
A11: Code | B11: ASME B 36.10M
A12: Size(in) | B12: 0.5 | C12: 0.75 | D12: 1 | E12: 1.5 | F12: 2 | G12: 3 | H12: 4 | I12: 6 | J12: 8 | K12: 10 | L12: 12 | M12: 14 | N12: 16 | O12: 18 | P12: 20 | Q12: 22 | R12: 24
A13: O.D.mm | B13: 21.3 | C13: 26.7 | D13: 33.4 | E13: 48.3 | F13: 60.3 | G13: 88.9 | H13: 114.3 | I13: 168.3 | J13: 219.1 | K13: 273.1 | L13: 323.9 | M13: 355.6 | N13: 406.4 | O13: 457 | P13: 508 | Q13: 559 | R13: 610
A14: Sch. | B14: 160 | C14: 160 | D14: 160 | E14: 160 | F14: 80 | G14: 80 | H14: 80 | I14: 80 | J14: 40 | K14: 40 | L14: 40 | M14: 40 | N14: 40 | O14: 40 | P14: 40 | Q14: - | R14: 40
A15: WT. mm | B15: 7.47 | C15: 5.56 | D15: 6.35 | E15: 7.14 | F15: 5.54 | G15: 7.62 | H15: 8.56 | I15: 10.97 | J15: 8.18 | K15: 9.27 | L15: 10.31 | M15: 11.1 | N15: 12.7 | O15: 14.27 | P15: 15.1 | Q15: 15.88 | R15: 17.47
A16: TYPE | B16: Seamless | O16: EFW, 100% RT
A17: MOC | B17: ASTM A 106 Gr. B | O17: ASTM A 671 - CC60 Class 22
A18: Ends | B18: BE
A19: Fittings Data
A20: TYPE | B20: Butt Weld (SCH to match pipe), Seamless | O20: Butt Weld (SCH to match pipe), Welded
A21: MOC | B21: ASTM A 234 Gr. WPB | O21: ASTM A 420 Gr. WPL6
A22: Elbow | B22: ASME B 16.9
A23: Tee | B23: ASME B 16.9
A24: Red. | B24: ASME B 16.9
A25: Cap | B25: ASME B 16.9
A26: Plug | B26: Hex Head Plug, ASME B 16.11
A27: Weldolet | B27: MSS SP 97, ASTM A 105N
A28: Flange
A29: MOC | B29: ASTM A 105N
A30: FACE | B30: 300# RF, Serrated Finish
A31: TYPE | B31: Weld Neck, ASME B 16.5, Butt Welding ends as per ASME B 16.25
A32: Spectacle Blind/Spacer Blinds
A33: MOC | B33: ASTM A 105N
A34: Spectacle | B34: ASME B 16.48 | M34: Spacer and blind as per ASME B 16.48
A35: Bolts/ Nuts/ Gaskets
A36: Stud Bolts | B36: ASTM A 193 Gr. B7M, XYLAR 2 + XYLAN 1070 coated with minimum combined thickness of 50μm
A37: Hex Nuts | B37: ASTM A 194 Gr. 2HM, XYLAR 2 + XYLAN 1070 coated with minimum combined thickness of 50μm
A38: Gasket | B38: ASME B 16.20, 4.5mm, SS316/SS316L Spiral Wound with Flexible Graphite (F.G.) filler
A39: Valves
A40: Rating | B40: =VLOOKUP(F3,INDEX!B:J,2,0)&", RF" -> #VALUE!
...

Sheet D1
A1: #VALUE! | F1: PIPING MATERIAL SPECIFICATION | Q1: Rev: C0
F2: Piping Class | J2: Material | M2: C.A | O2: Mill Tol | Q2: Sheet NO
F3: =MID(CELL("filename",A4),FIND("]",CELL("filename",A4))+1,255) -> #VALUE! | H3: =VLOOKUP(F3,INDEX!B:J,2,0) -> #VALUE! | J3: =VLOOKUP(F3,INDEX!B:J,4,0) -> #VALUE! | M3: =VLOOKUP(F3,INDEX!B:J,5,0) -> #VALUE! | O3: =VLOOKUP(F3,INDEX!B:AF,17,0) -> #VALUE! | Q3: =VLOOKUP(F3,INDEX!B:J,9,0) -> #VALUE!
F4: Design Code: | I4: =VLOOKUP(F3,INDEX!B:AF,18,0) -> #VALUE!
F5: Service: | H5: =VLOOKUP(F3,INDEX!B:J,6,0) -> #VALUE!
F6: Branch Chart: | I6: =VLOOKUP(F3,INDEX!B:AF,16,0) -> #VALUE!
A7: Pressure-Temperature Rating
A8: Press., barg | B8: =VLOOKUP(F3,INDEX!B:AF,20,0) -> #VALUE! | D8: =VLOOKUP(F3,INDEX!B:AF,21,0) -> #VALUE! | F8: =VLOOKUP(F3,INDEX!B:AF,22,0) -> #VALUE! | H8: =VLOOKUP(F3,INDEX!B:AF,23,0) -> #VALUE! | J8: =VLOOKUP(F3,INDEX!B:AF,24,0) -> #VALUE! | P8: Hydrotest Pr. (barg)
A9: Temp., °C | B9: =VLOOKUP(F3,INDEX!B:Z,19,0)&" to 38" -> #VALUE! | D9: 50 | F9: 100 | H9: 150 | J9: 200 | P9: =B8*1.5 -> #VALUE!
A10: Pipe Data
A11: Code | B11: ASME B 36.10M
A12: Size(in) | B12: 0.5 | C12: 0.75 | D12: 1 | E12: 1.5 | F12: 2 | G12: 3 | H12: 4 | I12: 6 | J12: 8 | K12: 10 | L12: 12 | M12: 14 | N12: 16 | O12: 18 | P12: 20 | Q12: 22 | R12: 24
A13: O.D.mm | B13: 21.3 | C13: 26.7 | D13: 33.4 | E13: 48.3 | F13: 60.3 | G13: 88.9 | H13: 114.3 | I13: 168.3 | J13: 219.1 | K13: 273.1 | L13: 323.9 | M13: 355.6 | N13: 406.4 | O13: 457 | P13: 508 | Q13: 559 | R13: 610
A14: Sch. | B14: 160 | C14: 160 | D14: 160 | E14: 160 | F14: 160 | G14: 80 | H14: 80 | I14: 80 | J14: 80 | K14: 80 | L14: 80 | M14: 80 | N14: 80 | O14: 80 | P14: 80 | Q14: 80 | R14: 80
A15: WT. mm | B15: 7.47 | C15: 5.56 | D15: 6.35 | E15: 7.14 | F15: 8.74 | G15: 7.62 | H15: 8.56 | I15: 10.97 | J15: 12.7 | K15: 15.08 | L15: 17.47 | M15: 19.05 | N15: 21.44 | O15: 23.82 | P15: 26.19 | Q15: 28.57 | R15: 30.96
A16: TYPE | B16: Seamless | O16: EFW, 100% RT
A17: MOC | B17: ASTM A 106 Gr. B | L17: ASTM A 333 Gr.6 | O17: ASTM A 671 - CC60 Class 22
A18: Ends | B18: BE
A19: Fittings Data
A20: TYPE | B20: Butt Weld (SCH to match pipe), Seamless | O20: Butt Weld (SCH to match pipe), Welded
A21: MOC | B21: ASTM A 234 Gr. WPB | L21: ASTM A 420 Gr. WPL6
A22: Elbow | B22: ASME B 16.9
A23: Tee | B23: ASME B 16.9
A24: Red. | B24: ASME B 16.9
A25: Cap | B25: ASME B 16.9
A26: Plug | B26: Hex Head Plug, ASME B 16.11
A27: Weldolet | B27: MSS SP 97, ASTM A 105N
A28: Flange
A29: MOC | B29: ASTM A 105N
A30: FACE | B30: 600# RF, Serrated Finish
A31: TYPE | B31: Weld Neck, ASME B 16.5, Butt Welding ends as per ASME B 16.25
A32: Spectacle Blind/Spacer Blinds
A33: MOC | B33: ASTM A 105N
A34: Spectacle | B34: ASME B 16.48 | M34: Spacer and blind as per ASME B 16.48
A35: Bolts/ Nuts/ Gaskets
A36: Stud Bolts | B36: ASTM A 193 Gr. B7M, XYLAR 2 + XYLAN 1070 coated with minimum combined thickness of 50μm
A37: Hex Nuts | B37: ASTM A 194 Gr. 2HM, XYLAR 2 + XYLAN 1070 coated with minimum combined thickness of 50μm
A38: Gasket | B38: ASME B 16.20, 4.5mm, SS316/SS316L Spiral Wound with Flexible Graphite (F.G.) filler
A39: Valves
A40: Rating | B40: =VLOOKUP(F3,INDEX!B:J,2,0)&", RF" -> #VALUE!
...

Sheet E1
A1: #VALUE! | F1: PIPING MATERIAL SPECIFICATION | Q1: Rev: C0
F2: Piping Class | J2: Material | M2: C.A | O2: Mill Tol | Q2: Sheet No.
F3: =MID(CELL("filename",A4),FIND("]",CELL("filename",A4))+1,255) -> #VALUE! | H3: =VLOOKUP(F3,INDEX!B:J,2,0) -> #VALUE! | J3: =VLOOKUP(F3,INDEX!B:J,4,0) -> #VALUE! | M3: =VLOOKUP(F3,INDEX!B:J,5,0) -> #VALUE! | O3: =VLOOKUP(F3,INDEX!B:AF,17,0) -> #VALUE! | Q3: =VLOOKUP(F3,INDEX!B:J,9,0) -> #VALUE!
F4: Design Code: | I4: =VLOOKUP(F3,INDEX!B:AF,18,0) -> #VALUE!
F5: Service: | H5: =VLOOKUP(F3,INDEX!B:J,6,0) -> #VALUE!
F6: Branch Chart: | I6: =VLOOKUP(F3,INDEX!B:AF,16,0) -> #VALUE!
A7: Pressure-Temperature Rating
A8: Press., barg | B8: =VLOOKUP(F3,INDEX!B:AF,20,0) -> #VALUE! | D8: =VLOOKUP(F3,INDEX!B:AF,21,0) -> #VALUE! | F8: =VLOOKUP(F3,INDEX!B:AF,22,0) -> #VALUE! | H8: =VLOOKUP(F3,INDEX!B:AF,23,0) -> #VALUE! | J8: =VLOOKUP(F3,INDEX!B:AF,24,0) -> #VALUE! | P8: Hydrotest Pr. (barg)
A9: Temp., °C | B9: =VLOOKUP(F3,INDEX!B:Z,19,0)&" to 38" -> #VALUE! | D9: 50 | F9: 100 | H9: 150 | J9: 200 | P9: =B8*1.5 -> #VALUE!
A10: Pipe Data
A11: Code | B11: ASME B 36.10M
A12: Size(in) | B12: 0.5 | C12: 0.75 | D12: 1 | E12: 1.5 | F12: 2 | G12: 3 | H12: 4 | I12: 6 | J12: 8 | K12: 10 | L12: 12 | M12: 14 | N12: 16 | O12: 18 | P12: 20 | Q12: 22 | R12: 24
A13: O.D.mm | B13: 21.3 | C13: 26.7 | D13: 33.4 | E13: 48.3 | F13: 60.3 | G13: 88.9 | H13: 114 | I13: 168.3 | J13: 219 | K13: 273.1 | L13: 323.9 | M13: 355.6 | N13: 406.4 | O13: 457 | P13: 508 | Q13: 559 | R13: 610
A14: Sch. | B14: 160 | C14: 160 | D14: 160 | E14: 160 | F14: 160 | G14: 160 | H14: 120 | I14: 120 | J14: 120 | K14: 120 | L14: 120 | M14: 120 | N14: 120 | O14: 120 | P14: 120 | Q14: 120 | R14: 120
A15: WT. mm | B15: 7.47 | C15: 5.56 | D15: 6.35 | E15: 7.14 | F15: 8.7 | G15: 11.12 | H15: 11.1 | I15: 14.27 | J15: 18.3 | K15: 21.44 | L15: 25.4 | M15: 27.79 | N15: 30.96 | O15: 34.92 | P15: 38.1 | Q15: 41.27 | R15: 46.02
A16: TYPE | B16: Seamless | O16: EFW, 100% RT
A17: MOC | B17: ASTM A 106 Gr. B | J17: ASTM A 333 Gr.6 | O17: ASTM A 671 - CC60 Class 22
A18: Ends | B18: BE
A19: Fittings Data
A20: TYPE | B20: Butt Weld (SCH to match pipe), Seamless | O20: Butt Weld (SCH to match pipe), Welded
A21: MOC | B21: ASTM A 234 Gr. WPB | J21: ASTM A 420 Gr. WPL6
A22: Elbow | B22: ASME B 16.9
A23: Tee | B23: ASME B 16.9
A24: Red. | B24: ASME B 16.9
A25: Cap | B25: ASME B 16.9
A26: Plug | B26: Hex Head Plug, ASME B 16.11
A27: Weldolet | B27: MSS SP 97, ASTM A 105N
A28: Flange
A29: MOC | B29: ASTM A 105N
A30: FACE | B30: 1500#, RTJ | F30: 900#, RTJ
A31: TYPE | B31: Weld Neck, ASME B16.5, Butt welding ends as per ASME 16.25, Note 8,9
A32: Spectacle Blind/Spacer Blinds
A33: MOC | B33: ASTM A 105N
A34: Spectacle | B34: ASME B 16.48 | M34: Spacer and blind as per ASME B 16.48
A35: Bolts/ Nuts/ Gaskets
A36: Stud Bolts | B36: ASTM A 193 Gr. B7M, XYLAR 2 + XYLAN 1070 coated with minimum combined thickness of 50μm
A37: Hex Nuts | B37: ASTM A 194 Gr. 2HM, XYLAR 2 + XYLAN 1070 coated with minimum combined thickness of 50μm
A38: Gasket | B38: ASME B 16.20, OCT ring of Soft Iron with Max. Hardness of 90 BHN, HDG
A39: Valves
A40: Rating | B40: =VLOOKUP(F3,INDEX!B:J,2,0)&", RTJ" -> #VALUE!
...

Sheet F1
A1: #VALUE! | F1: PIPING MATERIAL SPECIFICATION | Q1: Rev: C0
F2: Piping Class | J2: Material | M2: C.A | O2: Mill Tol | Q2: Sheet No.
F3: =MID(CELL("filename",A4),FIND("]",CELL("filename",A4))+1,255) -> #VALUE! | H3: =VLOOKUP(F3,INDEX!B:J,2,0) -> #VALUE! | J3: =VLOOKUP(F3,INDEX!B:J,4,0) -> #VALUE! | M3: =VLOOKUP(F3,INDEX!B:J,5,0) -> #VALUE! | O3: =VLOOKUP(F3,INDEX!B:AF,17,0) -> #VALUE! | Q3: =VLOOKUP(F3,INDEX!B:J,9,0) -> #VALUE!
F4: Design Code: | I4: =VLOOKUP(F3,INDEX!B:AF,18,0) -> #VALUE!
F5: Service: | H5: =VLOOKUP(F3,INDEX!B:J,6,0) -> #VALUE!
F6: Branch Chart: | I6: =VLOOKUP(F3,INDEX!B:AF,16,0) -> #VALUE!
A7: Pressure-Temperature Rating
A8: Press., barg | B8: =VLOOKUP(F3,INDEX!B:AF,20,0) -> #VALUE! | D8: =VLOOKUP(F3,INDEX!B:AF,21,0) -> #VALUE! | F8: =VLOOKUP(F3,INDEX!B:AF,22,0) -> #VALUE! | H8: =VLOOKUP(F3,INDEX!B:AF,23,0) -> #VALUE! | J8: =VLOOKUP(F3,INDEX!B:AF,24,0) -> #VALUE! | P8: Hydrotest Pr. (barg)
A9: Temp., °C | B9: =VLOOKUP(F3,INDEX!B:Z,19,0)&" to 38" -> #VALUE! | D9: 50 | F9: 100 | H9: 150 | J9: 200 | P9: =B8*1.5 -> #VALUE!
A10: Pipe Data
A11: Code | B11: ASME B 36.10M
A12: Size(in) | B12: 0.5 | C12: 0.75 | D12: 1 | E12: 1.5 | F12: 2 | G12: 3 | H12: 4 | I12: 6 | J12: 8 | K12: 10 | L12: 12 | M12: 14 | N12: 16 | O12: 18 | P12: 20 | Q12: 22 | R12: 24
A13: O.D.mm | B13: 21.3 | C13: 26.7 | D13: 33.4 | E13: 48.3 | F13: 60.3 | G13: 88.9 | H13: 114.3 | I13: 168.3 | J13: 219.1 | K13: 273.1 | L13: 323.9 | M13: 355.6 | N13: 406.4 | O13: 457 | P13: 508 | Q13: 559 | R13: 610
A14: Sch. | B14: XXS | C14: XXS | D14: XXS | E14: XXS | F14: 160 | G14: 160 | H14: 160 | I14: 160 | J14: XXS | K14: 140 | L14: 160 | M14: 160 | N14: 140 | O14: 160 | P14: 140 | Q14: 160 | R14: 140
A15: WT. mm | B15: 7.47 | C15: 7.82 | D15: 9.09 | E15: 10.15 | F15: 8.74 | G15: 11.13 | H15: 13.49 | I15: 18.26 | J15: 22.23 | K15: 25.4 | L15: 33.32 | M15: 35.71 | N15: 36.53 | O15: 45.24 | P15: 44.45 | Q15: 53.98 | R15: 52.37
A16: TYPE | B16: Seamless | O16: LSAW, 100% RT
A17: MOC | B17: API 5L Gr, X60 PSL-2 | O17: API 5L Gr, X60 PSL-2
A18: Ends | B18: BE
A19: Fittings Data
A20: TYPE | B20: Butt Weld (SCH to match pipe), Seamless | O20: Butt Weld (SCH to match pipe), Welded
A21: MOC | B21: ASTM A 860 WPHY 60
A22: Elbow | B22: ASME B 16.9
A23: Tee | B23: ASME B 16.9
A24: Red. | B24: ASME B 16.9
A25: Cap | B25: ASME B 16.9
A26: Plug | B26: Hex Head Plug, ASME B 16.11
A27: Weldolet | B27: MSS SP 97, ASTM A 694 F60
A28: Flange
A29: MOC | B29: ASTM A 694 F60
A30: FACE | B30: 1500#, RTJ
A31: WN Flange | B31: Weld Neck, ASME B16.5, Butt welding ends as per ASME 16.25, RTJ, Note 8,9
A32: Compact Flange | G32: WN Compact Flange (Norsok Standard L-005)* To be used for layout contraint.
A33: Hub Connector | G33: Seal Ring - ASTM A 182 F 316L, Hub and Blind Hub - ASTM A 694 F60, Clamp - AISI 4140, Bolt Material as below * To be used where ANSI or Compact Flange not suitable.
A34: Spectacle Blind/Spacer Blinds
A35: MOC | B35: ASTM A 694 F60
A36: Spectacle | B36: ASME B 16.48 | M36: Spacer and blind as per ASME B 16.48
A37: Bolts/ Nuts/ Gaskets
A38: Stud Bolts | B38: ASTM A 193 Gr. B7M, XYLAR 2 + XYLAN 1070 coated with minimum combined thickness of 50μm
A39: Hex Nuts | B39: ASTM A 194 Gr. 2HM, XYLAR 2 + XYLAN 1070 coated with minimum combined thickness of 50μm
A40: Gasket | B40: ASME B 16.20, OCT ring of Soft Iron with Max. Hardness of 90 BHN, HDG
...

Sheet G1
A1: #VALUE! | F1: PIPING MATERIAL SPECIFICATION | Q1: Rev: C0
F2: Piping Class | J2: Material | M2: C.A | O2: Mill Tol | Q2: Sheet No.
F3: =MID(CELL("filename",A4),FIND("]",CELL("filename",A4))+1,255) -> #VALUE! | H3: =VLOOKUP(F3,INDEX!B:J,2,0) -> #VALUE! | J3: =VLOOKUP(F3,INDEX!B:J,4,0) -> #VALUE! | M3: =VLOOKUP(F3,INDEX!B:J,5,0) -> #VALUE! | O3: =VLOOKUP(F3,INDEX!B:AF,17,0) -> #VALUE! | Q3: =VLOOKUP(F3,INDEX!B:J,9,0) -> #VALUE!
F4: Design Code: | I4: =VLOOKUP(F3,INDEX!B:AF,18,0) -> #VALUE!
F5: Service: | H5: =VLOOKUP(F3,INDEX!B:J,6,0) -> #VALUE!
F6: Branch Chart: | I6: =VLOOKUP(F3,INDEX!B:AF,16,0) -> #VALUE!
A7: Pressure-Temperature Rating
A8: Press., barg | B8: =VLOOKUP(F3,INDEX!B:AF,20,0) -> #VALUE! | D8: =VLOOKUP(F3,INDEX!B:AF,21,0) -> #VALUE! | F8: =VLOOKUP(F3,INDEX!B:AF,22,0) -> #VALUE! | H8: 360 | J8: =VLOOKUP(F3,INDEX!B:AF,23,0) -> #VALUE! | L8: =VLOOKUP(F3,INDEX!B:AF,24,0) -> #VALUE! | P8: Hydrotest Pr. (barg)
A9: Temp., °C | B9: =VLOOKUP(F3,INDEX!B:Z,19,0)&" to 38" -> #VALUE! | D9: 50 | F9: 100 | H9: 120 | J9: 150 | L9: 200 | P9: =B8*1.5 -> #VALUE!
A10: Pipe Data
A11: Code | B11: ASME B 36.10M
A12: Size(in) | B12: 0.5 | C12: 0.75 | D12: 1 | E12: 1.5 | F12: 2 | G12: 3 | H12: 4 | I12: 6 | J12: 8 | K12: 10 | L12: 12 | M12: 14 | N12: 16 | O12: 18 | P12: 20 | Q12: 22 | R12: 24
A13: O.D.mm | B13: 21.3 | C13: 26.7 | D13: 33.4 | E13: 48.3 | F13: 60.3 | G13: 88.9 | H13: 114.3 | I13: 168.3 | J13: 219.1 | K13: 273.1 | L13: 323.9 | M13: 355.6 | N13: 406.4 | O13: 457 | P13: 508 | Q13: 559 | R13: 610
A14: Sch. | B14: XXS | C14: XXS | D14: XXS | E14: XXS | F14: - | G14: XXS | H14: - | I14: - | J14: - | K14: - | L14: - | M14: - | N14: - | O14: - | P14: - | Q14: - | R14: -
A15: WT. mm | B15: 7.47 | C15: 7.82 | D15: 9.09 | E15: 10.15 | F15: 11.2 | G15: 15.24 | H15: 18.13 | I15: 25.06 | J15: 31.58 | K15: 38.5 | L15: 45.02 | M15: 49.11 | N15: 55.63 | O15: 62.12 | P15: 68.67 | Q15: 75.19 | R15: 81.77
A16: TYPE | B16: Seamless | O16: LSAW, 100% RT
A17: MOC | B17: API 5L Gr, X60 PSL-2 | O17: API 5L Gr, X60 PSL-2
A18: Ends | B18: BE
A19: Fittings Data
A20: TYPE | B20: Butt Weld (SCH to match pipe), Seamless | O20: Butt Weld (SCH to match pipe), Welded
A21: MOC | B21: ASTM A 860 WPHY 60
A22: Elbow | B22: ASME B 16.9
A23: Tee | B23: ASME B 16.9
A24: Red. | B24: ASME B 16.9
A25: Cap | B25: ASME B 16.9
A26: Plug | B26: Hex Head Plug, ASME B 16.11
A27: Weldolet | B27: MSS SP 97, ASTM A 694 F60
A28: Flange
A29: MOC | B29: ASTM A 694 F60
A30: FACE | B30: 1500#, RTJ
A31: WN Flange | B31: Weld Neck, ASME B16.5, Butt welding ends as per ASME 16.25, RTJ, Note 8,9
A32: Compact Flange | G32: WN Compact Flange (Norsok Standard L-005)* To be used for layout contraint.
A33: Hub Connector | G33: Seal Ring - ASTM A 182 F 316L, Hub and Blind Hub - ASTM A 694 F60, Clamp - AISI 4140, Bolt Material as below * To be used where ANSI or Compact Flange not suitable.
A34: Spectacle Blind/Spacer Blinds
A35: MOC | B35: ASTM A 694 F60
A36: Spectacle | B36: ASME B 16.48 | M36: Spacer and Blind as per ASME B 16.48
A37: Bolts/ Nuts/ Gaskets
A38: Stud Bolts | B38: ASTM A 193 Gr. B7M, XYLAR 2 + XYLAN 1070 coated with minimum combined thickness of 50μm
A39: Hex Nuts | B39: ASTM A 194 Gr. 2HM, XYLAR 2 + XYLAN 1070 coated with minimum combined thickness of 50μm
A40: Gasket | B40: ASME B 16.20, OCT ring of Soft Iron with Max. Hardness of 90 BHN, HDG
...

Sheet A1N
A1: #VALUE! | F1: PIPING MATERIAL SPECIFICATION | T1: Rev: C0
F2: Piping Class | J2: Material | N2: C.A | Q2: Mill Tol | T2: Sheet No.
F3: =MID(CELL("filename",A4),FIND("]",CELL("filename",A4))+1,255) -> #VALUE! | H3: =VLOOKUP(F3,INDEX!B:J,2,0) -> #VALUE! | J3: =VLOOKUP(F3,INDEX!B:J,4,0) -> #VALUE! | N3: =VLOOKUP(F3,INDEX!B:J,5,0) -> #VALUE! | Q3: =VLOOKUP(F3,INDEX!B:AF,17,0) -> #VALUE! | T3: =VLOOKUP(F3,INDEX!B:J,9,0) -> #VALUE!
F4: Design Code: | I4: =VLOOKUP(F3,INDEX!B:AF,18,0) -> #VALUE!
F5: Service: | I5: =VLOOKUP(F3,INDEX!B:J,6,0) -> #VALUE!
F6: Branch Chart: | I6: =VLOOKUP(F3,INDEX!B:AF,16,0) -> #VALUE!
A7: Pressure-Temperature Rating
A8: Press., barg | B8: =VLOOKUP(F3,INDEX!B:AF,20,0) -> #VALUE! | D8: =VLOOKUP(F3,INDEX!B:AF,21,0) -> #VALUE! | F8: =VLOOKUP(F3,INDEX!B:AF,22,0) -> #VALUE! | H8: =VLOOKUP(F3,INDEX!B:AF,23,0) -> #VALUE! | J8: =VLOOKUP(F3,INDEX!B:AF,24,0) -> #VALUE! | L8: =VLOOKUP(F3,INDEX!B:AF,25,0) -> #VALUE! | P8: Hydrotest Pr. (barg)
A9: Temp., °C | B9: =VLOOKUP(F3,INDEX!B:Z,19,0)&" to 38" -> #VALUE! | D9: 50 | F9: 100 | H9: 150 | J9: 200 | L9: 250 | P9: =B8*1.5 -> #VALUE!
A10: Pipe Data
A11: Code | B11: ASME B 36.10M
A12: Size(in) | B12: 0.5 | C12: 0.75 | D12: 1 | E12: 1.5 | F12: 2 | G12: 3 | H12: 4 | I12: 6 | J12: 8 | K12: 10 | L12: 12 | M12: 14 | N12: 16 | O12: 18 | P12: 20 | Q12: 22 | R12: 24 | S12: 26 | T12: 28 | U12: 30 | V12: 32
A13: O.D.mm | B13: 21.3 | C13: 26.7 | D13: 33.4 | E13: 48.3 | F13: 60.3 | G13: 88.9 | H13: 114.3 | I13: 168.3 | J13: 219.1 | K13: 273.1 | L13: 323.9 | M13: 355.6 | N13: 406.4 | O13: 457 | P13: 508 | Q13: 559 | R13: 610 | S13: 660 | T13: 711 | U13: 762 | V13: 812.8
A14: Sch. | B14: 160 | C14: 160 | D14: 160 | E14: 160 | F14: 80 | G14: 80 | H14: 80 | I14: 80 | J14: STD | K14: STD | L14: STD | M14: STD | N14: STD | O14: STD | P14: STD | Q14: STD | R14: STD | S14: STD | T14: STD | U14: XS | V14: XS
A15: WT. mm | B15: 7.47 | C15: 5.56 | D15: 6.35 | E15: 7.14 | F15: 5.54 | G15: 7.62 | H15: 8.56 | I15: 10.97 | J15: 8.18 | K15: 9.27 | L15: 9.53 | M15: 9.53 | N15: 9.53 | O15: 9.53 | P15: 9.53 | Q15: 9.53 | R15: 9.53 | S15: 9.53 | T15: 9.53 | U15: 12.7 | V15: 12.7
A16: TYPE | B16: Seamless | O16: LSAW, 100% RT
A17: MOC | B17: ASTM A 106 Gr. B | O17: API 5L Gr. B
A18: Ends | B18: BE
A19: Fittings Data
A20: TYPE | B20: Butt Weld (SCH to match pipe), Seamless | O20: Butt Weld (SCH to match pipe), Welded
A21: MOC | B21: ASTM A 234 Gr. WPB
A22: Elbow | B22: ASME B 16.9
A23: Tee | B23: ASME B 16.9
A24: Red. | B24: ASME B 16.9
A25: Cap | B25: ASME B 16.9
A26: Plug | B26: Hex Head Plug, ASME B 16.11
A27: Weldolet | B27: MSS SP 97, ASTM A 105N
A28: Flange
A29: MOC | B29: ASTM A 105N
A30: FACE | B30: 150# RF, Serrated Finish
A31: TYPE | B31: Weld Neck, ASME B 16.5/ 16.47A, Butt Welding ends as per ASME B 16.25
A32: Spectacle Blind/Spacer Blinds
A33: MOC | B33: ASTM A 105N
A34: Spectacle | B34: ASME B 16.48 | N34: Spacer and blind as per ASME B 16.48 (Note 5)
A35: Bolts/ Nuts/ Gaskets
A36: Stud Bolts | B36: ASTM A 193 Gr. B7M, XYLAR 2 + XYLAN 1070 coated with minimum combined thickness of 50μm
A37: Hex Nuts | B37: ASTM A 194 Gr. 2HM, XYLAR 2 + XYLAN 1070 coated with minimum combined thickness of 50μm
A38: Gasket | B38: ASME B 16.20, 4.5mm, SS316/SS316L Spiral Wound with Flexible Graphite (F.G.) filler
A39: Valves
A40: Rating | B40: =VLOOKUP(F3,INDEX!B:J,2,0)&", RF" -> #VALUE!
...

Sheet B1N
A1: #VALUE! | F1: PIPING MATERIAL SPECIFICATION | Q1: Rev: C0
F2: Piping Class | J2: Material | M2: C.A | O2: Mill Tol | Q2: Sheet No.
F3: =MID(CELL("filename",A4),FIND("]",CELL("filename",A4))+1,255) -> #VALUE! | H3: =VLOOKUP(F3,INDEX!B:J,2,0) -> #VALUE! | J3: =VLOOKUP(F3,INDEX!B:J,4,0) -> #VALUE! | M3: =VLOOKUP(F3,INDEX!B:J,5,0) -> #VALUE! | O3: =VLOOKUP(F3,INDEX!B:AF,17,0) -> #VALUE! | Q3: =VLOOKUP(F3,INDEX!B:J,9,0) -> #VALUE!
F4: Design Code: | I4: =VLOOKUP(F3,INDEX!B:AF,18,0) -> #VALUE!
F5: Service: | H5: =VLOOKUP(F3,INDEX!B:J,6,0) -> #VALUE!
F6: Branch Chart: | I6: =VLOOKUP(F3,INDEX!B:AF,16,0) -> #VALUE!
A7: Pressure-Temperature Rating
A8: Press., barg | B8: =VLOOKUP(F3,INDEX!B:AF,20,0) -> #VALUE! | D8: =VLOOKUP(F3,INDEX!B:AF,21,0) -> #VALUE! | F8: =VLOOKUP(F3,INDEX!B:AF,22,0) -> #VALUE! | H8: =VLOOKUP(F3,INDEX!B:AF,23,0) -> #VALUE! | J8: =VLOOKUP(F3,INDEX!B:AF,24,0) -> #VALUE! | L8: =VLOOKUP(F3,INDEX!B:AF,25,0) -> #VALUE! | P8: Hydrotest Pr. (barg)
A9: Temp., °C | B9: =VLOOKUP(F3,INDEX!B:Z,19,0)&" to 38" -> #VALUE! | D9: 50 | F9: 100 | H9: 150 | J9: 200 | L9: 250 | P9: =B8*1.5 -> #VALUE!
A10: Pipe Data
A11: Code | B11: ASME B 36.10M
A12: Size(in) | B12: 0.5 | C12: 0.75 | D12: 1 | E12: 1.5 | F12: 2 | G12: 3 | H12: 4 | I12: 6 | J12: 8 | K12: 10 | L12: 12 | M12: 14 | N12: 16 | O12: 18 | P12: 20 | Q12: 22 | R12: 24
A13: O.D.mm | B13: 21.3 | C13: 26.7 | D13: 33.4 | E13: 48.3 | F13: 60.3 | G13: 88.9 | H13: 114 | I13: 168.3 | J13: 219.1 | K13: 273.1 | L13: 323.9 | M13: 355.6 | N13: 406.4 | O13: 457 | P13: 508 | Q13: 559 | R13: 610
A14: Sch. | B14: 160 | C14: 160 | D14: 160 | E14: 160 | F14: 80 | G14: 80 | H14: 80 | I14: 80 | J14: 40 | K14: 40 | L14: 40 | M14: 40 | N14: 40 | O14: 40 | P14: 40 | Q14: - | R14: 40
A15: WT. mm | B15: 7.47 | C15: 5.56 | D15: 6.35 | E15: 7.14 | F15: 5.54 | G15: 7.62 | H15: 8.56 | I15: 10.97 | J15: 8.18 | K15: 9.27 | L15: 10.31 | M15: 11.1 | N15: 12.7 | O15: 14.27 | P15: 15.1 | Q15: 15.88 | R15: 17.47
A16: TYPE | B16: Seamless | O16: EFW, 100% RT
A17: MOC | B17: ASTM A 106 Gr. B | O17: ASTM A 671 - CC60 Class 22
A18: Ends | B18: BE
A19: Fittings Data
A20: TYPE | B20: Butt Weld (SCH to match pipe), Seamless | O20: Butt Weld (SCH to match pipe), Welded
A21: MOC | B21: ASTM A 234 Gr. WPB | N21: ASTM A 420 Gr. WPL6
A22: Elbow | B22: ASME B 16.9
A23: Tee | B23: ASME B 16.9
A24: Red. | B24: ASME B 16.9
A25: Cap | B25: ASME B 16.9
A26: Plug | B26: Hex Head Plug, ASME B 16.11
A27: Weldolet | B27: MSS SP 97, ASTM A 105N
A28: Flange
A29: MOC | B29: ASTM A 105N
A30: FACE | B30: 300# RF, Serrated Finish
A31: TYPE | B31: Weld Neck, ASME B 16.5, Butt Welding ends as per ASME B 16.25
A32: Spectacle Blind/Spacer Blinds
A33: MOC | B33: ASTM A 105N
A34: Spectacle | B34: ASME B 16.48 | M34: Spacer and blind as per ASME B 16.48
A35: Bolts/ Nuts/ Gaskets
A36: Stud Bolts | B36: ASTM A 193 Gr. B7M, XYLAR 2 + XYLAN 1070 coated with minimum combined thickness of 50μm
A37: Hex Nuts | B37: ASTM A 194 Gr. 2HM, XYLAR 2 + XYLAN 1070 coated with minimum combined thickness of 50μm
A38: Gasket | B38: ASME B 16.20, 4.5mm, SS316/SS316L Spiral Wound with Flexible Graphite (F.G.) filler
A39: Valves
A40: Rating | B40: =VLOOKUP(F3,INDEX!B:J,2,0)&", RF" -> #VALUE!
...

Sheet D1N
A1: #VALUE! | F1: PIPING MATERIAL SPECIFICATION | Q1: Rev: C0
F2: Piping Class | J2: Material | M2: C.A | O2: Mill Tol | Q2: Sheet No.
F3: =MID(CELL("filename",A4),FIND("]",CELL("filename",A4))+1,255) -> #VALUE! | H3: =VLOOKUP(F3,INDEX!B:J,2,0) -> #VALUE! | J3: =VLOOKUP(F3,INDEX!B:J,4,0) -> #VALUE! | M3: =VLOOKUP(F3,INDEX!B:J,5,0) -> #VALUE! | O3: =VLOOKUP(F3,INDEX!B:AF,17,0) -> #VALUE! | Q3: =VLOOKUP(F3,INDEX!B:J,9,0) -> #VALUE!
F4: Design Code: | I4: =VLOOKUP(F3,INDEX!B:AF,18,0) -> #VALUE!
F5: Service: | H5: =VLOOKUP(F3,INDEX!B:J,6,0) -> #VALUE!
F6: Branch Chart: | I6: =VLOOKUP(F3,INDEX!B:AF,16,0) -> #VALUE!
A7: Pressure-Temperature Rating
A8: Press., barg | B8: =VLOOKUP(F3,INDEX!B:AF,20,0) -> #VALUE! | D8: =VLOOKUP(F3,INDEX!B:AF,21,0) -> #VALUE! | F8: =VLOOKUP(F3,INDEX!B:AF,22,0) -> #VALUE! | H8: =VLOOKUP(F3,INDEX!B:AF,23,0) -> #VALUE! | J8: =VLOOKUP(F3,INDEX!B:AF,24,0) -> #VALUE! | L8: =VLOOKUP(F3,INDEX!B:AF,25,0) -> #VALUE! | P8: Hydrotest Pr. (barg)
A9: Temp., °C | B9: =VLOOKUP(F3,INDEX!B:Z,19,0)&" to 38" -> #VALUE! | D9: 50 | F9: 100 | H9: 150 | J9: 200 | L9: 250 | P9: =B8*1.5 -> #VALUE!
A10: Pipe Data
A11: Code | B11: ASME B 36.10M
A12: Size(in) | B12: 0.5 | C12: 0.75 | D12: 1 | E12: 1.5 | F12: 2 | G12: 3 | H12: 4 | I12: 6 | J12: 8 | K12: 10 | L12: 12 | M12: 14 | N12: 16 | O12: 18 | P12: 20 | Q12: 22 | R12: 24
A13: O.D.mm | B13: 21.3 | C13: 26.7 | D13: 33.4 | E13: 48.3 | F13: 60.3 | G13: 88.9 | H13: 114.3 | I13: 168.3 | J13: 219.1 | K13: 273.1 | L13: 323.9 | M13: 355.6 | N13: 406.4 | O13: 457 | P13: 508 | Q13: 559 | R13: 610
A14: Sch. | B14: 160 | C14: 160 | D14: 160 | E14: 160 | F14: 160 | G14: 80 | H14: 80 | I14: 80 | J14: 80 | K14: 80 | L14: 80 | M14: 80 | N14: 80 | O14: 80 | P14: 80 | Q14: 80 | R14: 80
A15: WT. mm | B15: 7.47 | C15: 5.56 | D15: 6.35 | E15: 7.14 | F15: 8.74 | G15: 7.62 | H15: 8.56 | I15: 10.97 | J15: 12.7 | K15: 15.08 | L15: 17.47 | M15: 19.05 | N15: 21.44 | O15: 23.82 | P15: 26.19 | Q15: 28.57 | R15: 30.96
A16: TYPE | B16: Seamless | O16: EFW, 100% RT
A17: MOC | B17: ASTM A 106 Gr. B | L17: ASTM A 333 Gr.6 | O17: ASTM A 671 - CC60 Class 22
A18: Ends | B18: BE
A19: Fittings Data
A20: TYPE | B20: Butt Weld (SCH to match pipe), Seamless | O20: Butt Weld (SCH to match pipe), Welded
A21: MOC | B21: ASTM A 234 Gr. WPB | L21: ASTM A 420 Gr. WPL6
A22: Elbow | B22: ASME B 16.9
A23: Tee | B23: ASME B 16.9
A24: Red. | B24: ASME B 16.9
A25: Cap | B25: ASME B 16.9
A26: Plug | B26: Hex Head Plug, ASME B 16.11
A27: Weldolet | B27: MSS SP 97, ASTM A 105N | O27: MSS SP 97, ASTM A 105
A28: Flange
A29: MOC | B29: ASTM A 105N
A30: FACE | B30: 600# RF, Serrated Finish
A31: TYPE | B31: Weld Neck, ASME B 16.5, Butt Welding ends as per ASME B 16.25
A32: Spectacle Blind/Spacer Blinds
A33: MOC | B33: ASTM A 105N
A34: Spectacle | B34: ASME B 16.48 | M34: Spacer and blind as per ASME B 16.48
A35: Bolts/ Nuts/ Gaskets
A36: Stud Bolts | B36: ASTM A 193 Gr. B7M, XYLAR 2 + XYLAN 1070 coated with minimum combined thickness of 50μm
A37: Hex Nuts | B37: ASTM A 194 Gr. 2HM, XYLAR 2 + XYLAN 1070 coated with minimum combined thickness of 50μm
A38: Gasket | B38: ASME B 16.20, 4.5mm, SS316/SS316L Spiral Wound with Flexible Graphite (F.G.) filler
A39: Valves
A40: Rating | B40: =VLOOKUP(F3,INDEX!B:J,2,0)&", RF" -> #VALUE!
...

Sheet E1N
A1: #VALUE! | F1: PIPING MATERIAL SPECIFICATION | Q1: Rev: C0
F2: Piping Class | J2: Material | M2: C.A | O2: Mill Tol | Q2: Sheet No.
F3: =MID(CELL("filename",A4),FIND("]",CELL("filename",A4))+1,255) -> #VALUE! | H3: =VLOOKUP(F3,INDEX!B:J,2,0) -> #VALUE! | J3: =VLOOKUP(F3,INDEX!B:J,4,0) -> #VALUE! | M3: =VLOOKUP(F3,INDEX!B:J,5,0) -> #VALUE! | O3: =VLOOKUP(F3,INDEX!B:AF,17,0) -> #VALUE! | Q3: =VLOOKUP(F3,INDEX!B:J,9,0) -> #VALUE!
F4: Design Code: | I4: =VLOOKUP(F3,INDEX!B:AF,18,0) -> #VALUE!
F5: Service: | H5: =VLOOKUP(F3,INDEX!B:J,6,0) -> #VALUE!
F6: Branch Chart: | I6: =VLOOKUP(F3,INDEX!B:AF,16,0) -> #VALUE!
A7: Pressure-Temperature Rating
A8: Press., barg | B8: =VLOOKUP(F3,INDEX!B:AF,20,0) -> #VALUE! | D8: =VLOOKUP(F3,INDEX!B:AF,21,0) -> #VALUE! | F8: =VLOOKUP(F3,INDEX!B:AF,22,0) -> #VALUE! | H8: =VLOOKUP(F3,INDEX!B:AF,23,0) -> #VALUE! | J8: =VLOOKUP(F3,INDEX!B:AF,24,0) -> #VALUE! | L8: =VLOOKUP(F3,INDEX!B:AF,25,0) -> #VALUE! | P8: Hydrotest Pr. (barg)
A9: Temp., °C | B9: =VLOOKUP(F3,INDEX!B:Z,19,0)&" to 38" -> #VALUE! | D9: 50 | F9: 100 | H9: 150 | J9: 200 | L9: 250 | P9: =B8*1.5 -> #VALUE!
A10: Pipe Data
A11: Code | B11: ASME B 36.10M
A12: Size(in) | B12: 0.5 | C12: 0.75 | D12: 1 | E12: 1.5 | F12: 2 | G12: 3 | H12: 4 | I12: 6 | J12: 8 | K12: 10 | L12: 12 | M12: 14 | N12: 16 | O12: 18 | P12: 20 | Q12: 22 | R12: 24
A13: O.D.mm | B13: 21.3 | C13: 26.7 | D13: 33.4 | E13: 48.3 | F13: 60.3 | G13: 88.9 | H13: 114 | I13: 168.3 | J13: 219 | K13: 273.1 | L13: 323.9 | M13: 355.6 | N13: 406.4 | O13: 457 | P13: 508 | Q13: 559 | R13: 610
A14: Sch. | B14: 160 | C14: 160 | D14: 160 | E14: 160 | F14: 160 | G14: 160 | H14: 120 | I14: 120 | J14: 120 | K14: 120 | L14: 120 | M14: 120 | N14: 120 | O14: 120 | P14: 120 | Q14: 120 | R14: 120
A15: WT. mm | B15: 7.47 | C15: 5.56 | D15: 6.35 | E15: 7.14 | F15: 8.7 | G15: 11.12 | H15: 11.1 | I15: 14.27 | J15: 18.3 | K15: 21.44 | L15: 25.4 | M15: 27.79 | N15: 30.96 | O15: 34.92 | P15: 38.1 | Q15: 41.27 | R15: 46.02
A16: TYPE | B16: Seamless | O16: EFW, 100% RT
A17: MOC | B17: ASTM A 106 Gr. B | J17: ASTM A 333 Gr.6 | O17: ASTM A 671 - CC60 Class 22
A18: Ends | B18: BE
A19: Fittings Data
A20: TYPE | B20: Butt Weld (SCH to match pipe), Seamless | O20: Butt Weld (SCH to match pipe), Welded
A21: MOC | B21: ASTM A 234 Gr. WPB | J21: ASTM A 420 Gr. WPL6
A22: Elbow | B22: ASME B 16.9
A23: Tee | B23: ASME B 16.9
A24: Red. | B24: ASME B 16.9
A25: Cap | B25: ASME B 16.9
A26: Plug | B26: Hex Head Plug, ASME B 16.11
A27: Weldolet | B27: MSS SP 97, ASTM A 105N | O27: MSS SP 97, ASTM A 105
A28: Flange
A29: MOC | B29: ASTM A 105N
A30: FACE | B30: 1500#, RTJ | F30: 900#, RTJ
A31: TYPE | B31: Weld Neck, ASME B16.5, Butt welding ends as per ASME 16.25, Note 8,9
A32: Spectacle Blind/Spacer Blinds
A33: MOC | B33: ASTM A 105N
A34: Spectacle | B34: ASME B 16.48 | M34: Spacer and blind as per ASME B 16.48
A35: Bolts/ Nuts/ Gaskets
A36: Stud Bolts | B36: ASTM A 193 Gr. B7M, XYLAR 2 + XYLAN 1070 coated with minimum combined thickness of 50μm
A37: Hex Nuts | B37: ASTM A 194 Gr. 2HM, XYLAR 2 + XYLAN 1070 coated with minimum combined thickness of 50μm
A38: Gasket | B38: ASME B 16.20, OCT ring of Soft Iron with Max. Hardness of 90 BHN, HDG
A39: Valves
A40: Rating | B40: =VLOOKUP(F3,INDEX!B:J,2,0)&", RTJ" -> #VALUE!
...

Sheet F1N
A1: #VALUE! | F1: PIPING MATERIAL SPECIFICATION | Q1: Rev: C0
F2: Piping Class | J2: Material | M2: C.A | O2: Mill Tol | Q2: Sheet No.
F3: =MID(CELL("filename",A4),FIND("]",CELL("filename",A4))+1,255) -> #VALUE! | H3: =VLOOKUP(F3,INDEX!B:J,2,0) -> #VALUE! | J3: =VLOOKUP(F3,INDEX!B:J,4,0) -> #VALUE! | M3: =VLOOKUP(F3,INDEX!B:J,5,0) -> #VALUE! | O3: =VLOOKUP(F3,INDEX!B:AF,17,0) -> #VALUE! | Q3: =VLOOKUP(F3,INDEX!B:J,9,0) -> #VALUE!
F4: Design Code: | I4: =VLOOKUP(F3,INDEX!B:AF,18,0) -> #VALUE!
F5: Service: | H5: =VLOOKUP(F3,INDEX!B:J,6,0) -> #VALUE!
F6: Branch Chart: | I6: =VLOOKUP(F3,INDEX!B:AF,16,0) -> #VALUE!
A7: Pressure-Temperature Rating
A8: Press., barg | B8: =VLOOKUP(F3,INDEX!B:AF,20,0) -> #VALUE! | D8: =VLOOKUP(F3,INDEX!B:AF,21,0) -> #VALUE! | F8: =VLOOKUP(F3,INDEX!B:AF,22,0) -> #VALUE! | H8: =VLOOKUP(F3,INDEX!B:AF,23,0) -> #VALUE! | J8: =VLOOKUP(F3,INDEX!B:AF,24,0) -> #VALUE! | P8: Hydrotest Pr. (barg)
A9: Temp., °C | B9: =VLOOKUP(F3,INDEX!B:Z,19,0)&" to 38" -> #VALUE! | D9: 50 | F9: 100 | H9: 150 | J9: 200 | P9: =B8*1.5 -> #VALUE!
A10: Pipe Data
A11: Code | B11: ASME B 36.10M
A12: Size(in) | B12: 0.5 | C12: 0.75 | D12: 1 | E12: 1.5 | F12: 2 | G12: 3 | H12: 4 | I12: 6 | J12: 8 | K12: 10 | L12: 12 | M12: 14 | N12: 16 | O12: 18 | P12: 20 | Q12: 22 | R12: 24
A13: O.D.mm | B13: 21.3 | C13: 26.7 | D13: 33.4 | E13: 48.3 | F13: 60.3 | G13: 88.9 | H13: 114.3 | I13: 168.3 | J13: 219.1 | K13: 273.1 | L13: 323.9 | M13: 355.6 | N13: 406.4 | O13: 457 | P13: 508 | Q13: 559 | R13: 610
A14: Sch. | B14: XXS | C14: XXS | D14: XXS | E14: XXS | F14: 160 | G14: 160 | H14: 160 | I14: 160 | J14: XXS | K14: 140 | L14: 160 | M14: 160 | N14: 140 | O14: 160 | P14: 140 | Q14: 160 | R14: 140
A15: WT. mm | B15: 7.47 | C15: 7.82 | D15: 9.09 | E15: 10.15 | F15: 8.74 | G15: 11.13 | H15: 13.49 | I15: 18.26 | J15: 22.23 | K15: 25.4 | L15: 33.32 | M15: 35.71 | N15: 36.53 | O15: 45.24 | P15: 44.45 | Q15: 53.98 | R15: 52.37
A16: TYPE | B16: Seamless | O16: LSAW, 100% RT
A17: MOC | B17: API 5L Gr, X60 PSL-2 | O17: API 5L Gr, X60 PSL-2
A18: Ends | B18: BE
A19: Fittings Data
A20: TYPE | B20: Butt Weld (SCH to match pipe), Seamless | O20: Butt Weld (SCH to match pipe), Welded
A21: MOC | B21: ASTM A 860 WPHY 60
A22: Elbow | B22: ASME B 16.9
A23: Tee | B23: ASME B 16.9
A24: Red. | B24: ASME B 16.9
A25: Cap | B25: ASME B 16.9
A26: Plug | B26: Hex Head Plug, ASME B 16.11
A27: Weldolet | B27: MSS SP 97, ASTM A 694 F60 | O27: MSS SP 97, ASTM A 694 F60
A28: Flange
A29: MOC | B29: ASTM A 694 F60
A30: FACE | B30: 1500#, RTJ
A31: WN Flange | B31: Weld Neck, ASME B16.5, Butt welding ends as per ASME 16.25, RTJ, Note 8,9
A32: Compact Flange | G32: WN Compact Flange (Norsok Standard L-005)* To be used for layout contraint.
A33: Hub Connector | G33: Seal Ring - ASTM A 182 F 316L, Hub and Blind Hub - ASTM A 694 F60, Clamp - AISI 4140, Bolt Material as below * To be used where ANSI or Compact Flange not suitable.
A34: Spectacle Blind/Spacer Blinds
A35: MOC | B35: ASTM A 694 F60
A36: Spectacle | B36: ASME B 16.48 | M36: Spacer and blind as per ASME B 16.48
A37: Bolts/ Nuts/ Gaskets
A38: Stud Bolts | B38: ASTM A 193 Gr. B7M, XYLAR 2 + XYLAN 1070 coated with minimum combined thickness of 50μm
A39: Hex Nuts | B39: ASTM A 194 Gr. 2HM, XYLAR 2 + XYLAN 1070 coated with minimum combined thickness of 50μm
A40: Gasket | B40: ASME B 16.20, OCT ring of Soft Iron with Max. Hardness of 90 BHN, HDG
...

Sheet G1N
A1: #VALUE! | F1: PIPING MATERIAL SPECIFICATION | Q1: Rev: C0
F2: Piping Class | J2: Material | M2: C.A | O2: Mill Tol | Q2: Sheet No.
F3: =MID(CELL("filename",A4),FIND("]",CELL("filename",A4))+1,255) -> #VALUE! | H3: =VLOOKUP(F3,INDEX!B:J,2,0) -> #VALUE! | J3: =VLOOKUP(F3,INDEX!B:J,4,0) -> #VALUE! | M3: =VLOOKUP(F3,INDEX!B:J,5,0) -> #VALUE! | O3: =VLOOKUP(F3,INDEX!B:AF,17,0) -> #VALUE! | Q3: =VLOOKUP(F3,INDEX!B:J,9,0) -> #VALUE!
F4: Design Code: | I4: =VLOOKUP(F3,INDEX!B:AF,18,0) -> #VALUE!
F5: Service: | H5: =VLOOKUP(F3,INDEX!B:J,6,0) -> #VALUE!
F6: Branch Chart: | I6: =VLOOKUP(F3,INDEX!B:AF,16,0) -> #VALUE!
A7: Pressure-Temperature Rating
A8: Press., barg | B8: =VLOOKUP(F3,INDEX!B:AF,20,0) -> #VALUE! | D8: =VLOOKUP(F3,INDEX!B:AF,21,0) -> #VALUE! | F8: =VLOOKUP(F3,INDEX!B:AF,22,0) -> #VALUE! | H8: =VLOOKUP(F3,INDEX!B:AF,23,0) -> #VALUE! | J8: =VLOOKUP(F3,INDEX!B:AF,24,0) -> #VALUE! | P8: Hydrotest Pr. (barg)
A9: Temp., °C | B9: =VLOOKUP(F3,INDEX!B:Z,19,0)&" to 38" -> #VALUE! | D9: 50 | F9: 100 | H9: 150 | J9: 200 | P9: =B8*1.5 -> #VALUE!
A10: Pipe Data
A11: Code | B11: ASME B 36.10M
A12: Size(in) | B12: 0.5 | C12: 0.75 | D12: 1 | E12: 1.5 | F12: 2 | G12: 3 | H12: 4 | I12: 6 | J12: 8 | K12: 10 | L12: 12 | M12: 14 | N12: 16 | O12: 18 | P12: 20 | Q12: 22 | R12: 24
A13: O.D.mm | B13: 21.3 | C13: 26.7 | D13: 33.4 | E13: 48.3 | F13: 60.3 | G13: 88.9 | H13: 114.3 | I13: 168.3 | J13: 219.1 | K13: 273.1 | L13: 323.9 | M13: 355.6 | N13: 406.4 | O13: 457 | P13: 508 | Q13: 559 | R13: 610
A14: Sch. | B14: XXS | C14: XXS | D14: XXS | E14: XXS | F14: - | G14: XXS | H14: - | I14: - | J14: - | K14: - | L14: - | M14: - | N14: - | O14: - | P14: - | Q14: - | R14: -
A15: WT. mm | B15: 7.47 | C15: 7.82 | D15: 9.09 | E15: 10.15 | F15: 11.2 | G15: 15.24 | H15: 18.13 | I15: 25.06 | J15: 31.58 | K15: 38.5 | L15: 45.02 | M15: 49.11 | N15: 55.63 | O15: 62.12 | P15: 68.67 | Q15: 75.19 | R15: 81.77
A16: TYPE | B16: Seamless | O16: LSAW, 100% RT
A17: MOC | B17: API 5L Gr, X60 PSL-2 | O17: API 5L Gr, X60 PSL-2
A18: Ends | B18: BE
A19: Fittings Data
A20: TYPE | B20: Butt Weld (SCH to match pipe), Seamless | O20: Butt Weld (SCH to match pipe), Welded
A21: MOC | B21: ASTM A 860 WPHY 60
A22: Elbow | B22: ASME B 16.9
A23: Tee | B23: ASME B 16.9
A24: Red. | B24: ASME B 16.9
A25: Cap | B25: ASME B 16.9
A26: Plug | B26: Hex Head Plug, ASME B 16.11
A27: Weldolet | B27: MSS SP 97, ASTM A 694 F60
A28: Flange
A29: MOC | B29: ASTM A 694 F60
A30: FACE | B30: 1500#, RTJ
A31: WN Flange | B31: Weld Neck, ASME B16.5, Butt welding ends as per ASME 16.25, RTJ, Note 8,9
A32: Compact Flange | G32: WN Compact Flange (Norsok Standard L-005)* To be used for layout contraint.
A33: Hub Connector | G33: Seal Ring - ASTM A 182 F 316L, Hub and Blind Hub - ASTM A 694 F60, Clamp - AISI 4140, Bolt Material as below * To be used where ANSI or Compact Flange not suitable.
A34: Spectacle Blind/Spacer Blinds
A35: MOC | B35: ASTM A 694 F60
A36: Spectacle | B36: ASME B 16.48 | M36: Spacer and blind as per ASME B 16.48
A37: Bolts/ Nuts/ Gaskets
A38: Stud Bolts | B38: ASTM A 193 Gr. B7M, XYLAR 2 + XYLAN 1070 coated with minimum combined thickness of 50μm
A39: Hex Nuts | B39: ASTM A 194 Gr. 2HM, XYLAR 2 + XYLAN 1070 coated with minimum combined thickness of 50μm
A40: Gasket | B40: ASME B 16.20, OCT ring of Soft Iron with Max. Hardness of 90 BHN, HDG
...

Sheet A2
A1: #VALUE! | F1: PIPING MATERIAL SPECIFICATION | Q1: Rev: C0
F2: Piping Class | J2: Material | M2: C.A | O2: Mill Tol | Q2: Sheet No.
F3: =MID(CELL("filename",A4),FIND("]",CELL("filename",A4))+1,255) -> #VALUE! | H3: =VLOOKUP(F3,INDEX!B:J,2,0) -> #VALUE! | J3: =VLOOKUP(F3,INDEX!B:J,4,0) -> #VALUE! | M3: =VLOOKUP(F3,INDEX!B:J,5,0) -> #VALUE! | O3: =VLOOKUP(F3,INDEX!B:AF,17,0) -> #VALUE! | Q3: =VLOOKUP(F3,INDEX!B:J,9,0) -> #VALUE!
